<?xml version="1.0" encoding="UTF-8"?>
<!-- Generated by org.testng.reporters.JUnitReportReporter -->
<testsuite hostname="SYN-FLX-001" name="scenarios.LOC.LocToOpnGetE1" tests="8" failures="2" timestamp="30 Jan 2020 18:24:57 GMT" time="8.913" errors="0">
  <testcase name="TC_02" time="1.005" classname="scenarios.LOC.LocToOpnGetE1">
    <failure type="java.lang.AssertionError" message="Test Failed">
      <![CDATA[java.lang.AssertionError: Test Failed
	at org.testng.Assert.fail(Assert.java:94)
	at scenarios.LOC.LocToOpnGetE1.LocToLoc_SuccessCases(LocToOpnGetE1.java:409)
	at scenarios.LOC.LocToOpnGetE1.TC_02(LocToOpnGetE1.java:118)
	at sun.reflect.NativeMethodAccessorImpl.invoke0(Native Method)
	at sun.reflect.NativeMethodAccessorImpl.invoke(Unknown Source)
	at sun.reflect.DelegatingMethodAccessorImpl.invoke(Unknown Source)
	at java.lang.reflect.Method.invoke(Unknown Source)
	at org.testng.internal.MethodInvocationHelper.invokeMethod(MethodInvocationHelper.java:86)
	at org.testng.internal.Invoker.invokeMethod(Invoker.java:646)
	at org.testng.internal.Invoker.invokeTestMethod(Invoker.java:823)
	at org.testng.internal.Invoker.invokeTestMethods(Invoker.java:1131)
	at org.testng.internal.TestMethodWorker.invokeTestMethods(TestMethodWorker.java:129)
	at org.testng.internal.TestMethodWorker.run(TestMethodWorker.java:112)
	at org.testng.TestRunner.privateRun(TestRunner.java:778)
	at org.testng.TestRunner.run(TestRunner.java:632)
	at org.testng.SuiteRunner.runTest(SuiteRunner.java:366)
	at org.testng.SuiteRunner.runSequentially(SuiteRunner.java:361)
	at org.testng.SuiteRunner.privateRun(SuiteRunner.java:319)
	at org.testng.SuiteRunner.run(SuiteRunner.java:268)
	at org.testng.SuiteRunnerWorker.runSuite(SuiteRunnerWorker.java:52)
	at org.testng.SuiteRunnerWorker.run(SuiteRunnerWorker.java:86)
	at org.testng.TestNG.runSuitesSequentially(TestNG.java:1225)
	at org.testng.TestNG.runSuitesLocally(TestNG.java:1150)
	at org.testng.TestNG.runSuites(TestNG.java:1075)
	at org.testng.TestNG.run(TestNG.java:1047)
	at org.testng.remote.AbstractRemoteTestNG.run(AbstractRemoteTestNG.java:126)
	at org.testng.remote.RemoteTestNG.initAndRun(RemoteTestNG.java:137)
	at org.testng.remote.RemoteTestNG.main(RemoteTestNG.java:58)
]]>
    </failure>
  </testcase> <!-- TC_02 -->
  <testcase name="TC_06" time="1.158" classname="scenarios.LOC.LocToOpnGetE1"/>
  <testcase name="TC_07" time="0.736" classname="scenarios.LOC.LocToOpnGetE1"/>
  <testcase name="TC_03" time="0.827" classname="scenarios.LOC.LocToOpnGetE1"/>
  <testcase name="TC_08" time="0.828" classname="scenarios.LOC.LocToOpnGetE1"/>
  <testcase name="TC_09" time="0.644" classname="scenarios.LOC.LocToOpnGetE1"/>
  <testcase name="TC_05" time="1.134" classname="scenarios.LOC.LocToOpnGetE1"/>
  <testcase name="TC_01" time="2.581" classname="scenarios.LOC.LocToOpnGetE1">
    <failure type="java.lang.AssertionError" message="Test Failed">
      <![CDATA[java.lang.AssertionError: Test Failed
	at org.testng.Assert.fail(Assert.java:94)
	at scenarios.LOC.LocToOpnGetE1.LocToLoc_SuccessCases(LocToOpnGetE1.java:409)
	at scenarios.LOC.LocToOpnGetE1.TC_01(LocToOpnGetE1.java:97)
	at sun.reflect.NativeMethodAccessorImpl.invoke0(Native Method)
	at sun.reflect.NativeMethodAccessorImpl.invoke(Unknown Source)
	at sun.reflect.DelegatingMethodAccessorImpl.invoke(Unknown Source)
	at java.lang.reflect.Method.invoke(Unknown Source)
	at org.testng.internal.MethodInvocationHelper.invokeMethod(MethodInvocationHelper.java:86)
	at org.testng.internal.Invoker.invokeMethod(Invoker.java:646)
	at org.testng.internal.Invoker.invokeTestMethod(Invoker.java:823)
	at org.testng.internal.Invoker.invokeTestMethods(Invoker.java:1131)
	at org.testng.internal.TestMethodWorker.invokeTestMethods(TestMethodWorker.java:129)
	at org.testng.internal.TestMethodWorker.run(TestMethodWorker.java:112)
	at org.testng.TestRunner.privateRun(TestRunner.java:778)
	at org.testng.TestRunner.run(TestRunner.java:632)
	at org.testng.SuiteRunner.runTest(SuiteRunner.java:366)
	at org.testng.SuiteRunner.runSequentially(SuiteRunner.java:361)
	at org.testng.SuiteRunner.privateRun(SuiteRunner.java:319)
	at org.testng.SuiteRunner.run(SuiteRunner.java:268)
	at org.testng.SuiteRunnerWorker.runSuite(SuiteRunnerWorker.java:52)
	at org.testng.SuiteRunnerWorker.run(SuiteRunnerWorker.java:86)
	at org.testng.TestNG.runSuitesSequentially(TestNG.java:1225)
	at org.testng.TestNG.runSuitesLocally(TestNG.java:1150)
	at org.testng.TestNG.runSuites(TestNG.java:1075)
	at org.testng.TestNG.run(TestNG.java:1047)
	at org.testng.remote.AbstractRemoteTestNG.run(AbstractRemoteTestNG.java:126)
	at org.testng.remote.RemoteTestNG.initAndRun(RemoteTestNG.java:137)
	at org.testng.remote.RemoteTestNG.main(RemoteTestNG.java:58)
]]>
    </failure>
  </testcase> <!-- TC_01 -->
</testsuite> <!-- scenarios.LOC.LocToOpnGetE1 -->
